{"trial_id": "00", "hyperparameters": {"space": [{"class_name": "Int", "config": {"name": "lstm_units", "default": null, "conditions": [], "min_value": 10, "max_value": 10, "step": 5, "sampling": "linear"}}, {"class_name": "Int", "config": {"name": "dense_units", "default": null, "conditions": [], "min_value": 10, "max_value": 20, "step": 5, "sampling": "linear"}}, {"class_name": "Choice", "config": {"name": "drop out values", "default": 0.2, "conditions": [], "values": [0.2, 0.35, 0.5], "ordered": true}}, {"class_name": "Choice", "config": {"name": "learning rate values", "default": 0.0001, "conditions": [], "values": [0.0001, 0.00055, 0.001], "ordered": true}}], "values": {"lstm_units": 10, "dense_units": 10, "drop out values": 0.35, "learning rate values": 0.00055}}, "metrics": {"metrics": {}}, "score": null, "best_step": 0, "status": "FAILED", "message": "Traceback (most recent call last):\n  File \"C:\\Users\\Anast\\pythonProject\\Crypto_Prise_Prediction\\venv\\CryptoVenv\\lib\\site-packages\\keras_tuner\\engine\\base_tuner.py\", line 266, in _try_run_and_update_trial\n    self._run_and_update_trial(trial, *fit_args, **fit_kwargs)\n  File \"C:\\Users\\Anast\\pythonProject\\Crypto_Prise_Prediction\\venv\\CryptoVenv\\lib\\site-packages\\keras_tuner\\engine\\base_tuner.py\", line 231, in _run_and_update_trial\n    results = self.run_trial(trial, *fit_args, **fit_kwargs)\n  File \"C:\\Users\\Anast\\pythonProject\\Crypto_Prise_Prediction\\venv\\CryptoVenv\\lib\\site-packages\\keras_tuner\\engine\\tuner.py\", line 287, in run_trial\n    obj_value = self._build_and_fit_model(trial, *args, **copied_kwargs)\n  File \"C:\\Users\\Anast\\pythonProject\\Crypto_Prise_Prediction\\venv\\CryptoVenv\\lib\\site-packages\\keras_tuner\\engine\\tuner.py\", line 214, in _build_and_fit_model\n    results = self.hypermodel.fit(hp, model, *args, **kwargs)\n  File \"C:\\Users\\Anast\\pythonProject\\Crypto_Prise_Prediction\\venv\\CryptoVenv\\lib\\site-packages\\keras_tuner\\engine\\hypermodel.py\", line 144, in fit\n    return model.fit(*args, **kwargs)\n  File \"C:\\Users\\Anast\\pythonProject\\Crypto_Prise_Prediction\\venv\\CryptoVenv\\lib\\site-packages\\keras\\utils\\traceback_utils.py\", line 70, in error_handler\n    raise e.with_traceback(filtered_tb) from None\n  File \"C:\\Users\\Anast\\AppData\\Local\\Temp\\__autograph_generated_file2w9gvxt1.py\", line 15, in tf__train_function\n    retval_ = ag__.converted_call(ag__.ld(step_function), (ag__.ld(self), ag__.ld(iterator)), None, fscope)\nValueError: in user code:\n\n    File \"C:\\Users\\Anast\\pythonProject\\Crypto_Prise_Prediction\\venv\\CryptoVenv\\lib\\site-packages\\keras\\engine\\training.py\", line 1249, in train_function  *\n        return step_function(self, iterator)\n    File \"C:\\Users\\Anast\\pythonProject\\Crypto_Prise_Prediction\\venv\\CryptoVenv\\lib\\site-packages\\keras\\engine\\training.py\", line 1233, in step_function  **\n        outputs = model.distribute_strategy.run(run_step, args=(data,))\n    File \"C:\\Users\\Anast\\pythonProject\\Crypto_Prise_Prediction\\venv\\CryptoVenv\\lib\\site-packages\\keras\\engine\\training.py\", line 1222, in run_step  **\n        outputs = model.train_step(data)\n    File \"C:\\Users\\Anast\\pythonProject\\Crypto_Prise_Prediction\\venv\\CryptoVenv\\lib\\site-packages\\keras\\engine\\training.py\", line 1024, in train_step\n        loss = self.compute_loss(x, y, y_pred, sample_weight)\n    File \"C:\\Users\\Anast\\pythonProject\\Crypto_Prise_Prediction\\venv\\CryptoVenv\\lib\\site-packages\\keras\\engine\\training.py\", line 1082, in compute_loss\n        return self.compiled_loss(\n    File \"C:\\Users\\Anast\\pythonProject\\Crypto_Prise_Prediction\\venv\\CryptoVenv\\lib\\site-packages\\keras\\engine\\compile_utils.py\", line 265, in __call__\n        loss_value = loss_obj(y_t, y_p, sample_weight=sw)\n    File \"C:\\Users\\Anast\\pythonProject\\Crypto_Prise_Prediction\\venv\\CryptoVenv\\lib\\site-packages\\keras\\losses.py\", line 152, in __call__\n        losses = call_fn(y_true, y_pred)\n    File \"C:\\Users\\Anast\\pythonProject\\Crypto_Prise_Prediction\\venv\\CryptoVenv\\lib\\site-packages\\keras\\losses.py\", line 284, in call  **\n        return ag_fn(y_true, y_pred, **self._fn_kwargs)\n    File \"C:\\Users\\Anast\\pythonProject\\Crypto_Prise_Prediction\\venv\\CryptoVenv\\lib\\site-packages\\keras\\losses.py\", line 2004, in categorical_crossentropy\n        return backend.categorical_crossentropy(\n    File \"C:\\Users\\Anast\\pythonProject\\Crypto_Prise_Prediction\\venv\\CryptoVenv\\lib\\site-packages\\keras\\backend.py\", line 5532, in categorical_crossentropy\n        target.shape.assert_is_compatible_with(output.shape)\n\n    ValueError: Shapes (32, 1) and (32, 3) are incompatible\n\n"}